Workbook

Sheet Cover
B2: AbarVa
B3: Enterprise Workforce Economics & AI-Native Delivery Model
B4: Workforce Taxonomy Master — v1.0
B6: PURPOSE | C6: Global workforce ontology + parametric cost, rate, agent-economics and pod substrate. Feeds the AbarVa estimation, business-case and roadmap engines for traditional and AI-native delivery.
B8: HOW TO USE
C9: 1. Edit ONLY blue-font cells (inputs) and the Assumptions tab. All black cells are formulas.
C10: 2. Assumptions drives the whole model — change a multiplier and every rate/cost reflows.
C11: 3. Rates are parametric: Market Base Rate x Provider Tier x Shore x Scarcity x Delivery. Nothing is a static guess.
C12: 4. Internal cost: fully-loaded annual / 2,080 = loaded hourly.
C13: 5. Provider names are anonymized archetypes (CONS-T1, SI-T1, SI-T2, ENG-B, AI-B). No real firms.
C14: 6. AI-native model estimates every capability twice: People vs People+Agents+Platforms.
C15: 7. 'Moves Binding' maps every taxonomy entity to the Move deliverable/estimation engine.
B17: SHEET INDEX
B18: Sheet | C18: Contents
B19: Assumptions | C19: Engine inputs: load factors, geo/provider/shore/scarcity multipliers, market base rates
B20: Exec Summary | C20: Counts + key model outputs
B21: Towers | C21: 21 delivery towers
B22: Capabilities | C22: 100+ capabilities by tower + agent-amenability
B23: Career Levels | C23: 10-level model with experience and base bands
B24: Roles | C24: Role taxonomy by tower/capability/level
B25: Geography | C25: 17 regions: salary/rate/scarcity/COL multipliers + shore
B26: Internal Cost Model | C26: Fully-loaded cost build-up by level
B27: Rate Intelligence | C27: Anonymized provider rate cards (parametric)
B28: Agent Economics | C28: Agent platform cost + productivity multipliers
B29: Delivery Pods | C29: Reusable human+agent pod library
... B31: Glossary | C31: Terms

Sheet Exec Summary
B2: EXECUTIVE SUMMARY
B3: AbarVa Workforce Economics — Taxonomy Master v1.0
B5: Dimension | C5: Count | D5: Note
B6: Delivery Towers | C6: 21 | D6: Full enterprise transformation coverage
B7: Capabilities | C7: 139 | D7: With scarcity + agent-amenability
B8: Roles (distinct families) | C8: 321 | D8: Across all 21 towers
B9: Priced staffable units | C9: 891 | D9: Role x eligible career level (Rate Card)
B10: Career Levels | C10: 10 | D10: Partner → Junior
B11: Geographies | C11: 17 | D11: Onshore / nearshore / offshore
B12: Provider Archetypes | C12: 23 | D12: Anonymized: CONS-T1, SI-T1, SI-T2, ENG-B, AI-B
B13: Agent Platforms | C13: 5 | D13: Provider-neutral + AbarVa Agents
B14: Delivery Pods | C14: 107 | D14: Reusable human+agent squads
B17: KEY MODEL OUTPUTS (live formulas)
B18: Loaded hourly — Senior (US baseline) | C18: =VLOOKUP("Senior",'Internal Cost Model'!$B$6:$F$15,5,FALSE)
B19: Offshore bill — SI-T2 Senior ($/hr) | C19: =VLOOKUP("Senior",Assumptions!$B$50:$D$59,2,FALSE)*VLOOKUP("SI-T2",Assumptions!$B$27:$C$31,2,FALSE)*INDEX(Assumptions!$C$36:$C$38,3)
B20: Onshore bill — CONS-T1 Principal ($/hr) | C20: =VLOOKUP("Principal",Assumptions!$B$50:$D$59,2,FALSE)*VLOOKUP("CONS-T1",Assumptions!$B$27:$C$31,2,FALSE)

Sheet Assumptions
B2: ASSUMPTIONS — model engine (edit blue cells)
B3: All downstream cost & rate formulas reference these cells.
B5: FULLY-LOADED COST COMPONENTS (% of base salary)
B6: Component | C6: % of base
B7: Bonus | C7: 0.15
B8: Equity | C8: 0.08
B9: Benefits | C9: 0.14
B10: Payroll Taxes | C10: 0.0765
B11: 401k Match | C11: 0.04
B12: Recruiting | C12: 0.03
B13: Training | C13: 0.025
B14: Bench / Utilization | C14: 0.12
B15: Facilities | C15: 0.05
B16: Technology Allocation | C16: 0.045
B17: Corporate Allocation | C17: 0.06
B18: Administrative Allocation | C18: 0.035
B19: Travel Allocation | C19: 0.02
B20: Total load factor | C20: =SUM(C7:C19) | F20: Loaded annual = base x (1 + total load factor)
B22: Billable hours / year | C22: 2080
B25: PROVIDER TIER MULTIPLIERS (vs market base bill rate)
B26: Tier | C26: Multiplier | F26: Archetype
B27: CONS-T1 | C27: 1.85 | F27: Premium strategy/advisory
B28: SI-T1 | C28: 1.25 | F28: Global system integrator
B29: SI-T2 | C29: 0.85 | F29: Industrialized offshore
B30: ENG-B | C30: 1.1 | F30: Engineering boutique
B31: AI-B | C31: 1.35 | F31: AI-native provider
B34: SHORE MULTIPLIERS
B35: Shore | C35: Multiplier
B36: Onshore | C36: 1
B37: Nearshore | C37: 0.72
B38: Offshore | C38: 0.45
B41: SCARCITY MULTIPLIERS (by role scarcity tier)
B42: Scarcity | C42: Multiplier
B43: High | C43: 1.3
B44: Medium | C44: 1.1
B45: Low | C45: 1
B48: MARKET BASE BILL RATE — onshore baseline ($/hr by level)
B49: Level | C49: Base $/hr | D49: Base salary (US, $)
B50: Partner | C50: 625 | D50: 520000
B51: Managing Director | C51: 525 | D51: 430000
...

Sheet Towers
B2: DELIVERY TOWERS
B4: ID | C4: Tower | D4: Scope
B5: TWR-01 | C5: Strategy & Transformation | D5: Vision, operating model, transformation strategy, value architecture
B6: TWR-02 | C6: Industry SMEs | D6: Vertical domain expertise (FS, healthcare, retail, manufacturing, public)
B7: TWR-03 | C7: Business Process | D7: Process design, reengineering, process mining, automation strategy
B8: TWR-04 | C8: Data & Analytics | D8: Data strategy, governance, engineering, BI, analytics, data products
B9: TWR-05 | C9: AI & GenAI | D9: AI/ML, GenAI, agentic AI, MLOps/LLMOps, responsible AI
B10: TWR-06 | C10: Digital Experience | D10: UX/UI, commerce, content, web/mobile experience platforms
B11: TWR-07 | C11: Marketing Technology | D11: MarTech, Adobe, journey orchestration, customer data
B12: TWR-08 | C12: Product Management | D12: Product strategy, ownership, discovery, lifecycle
B13: TWR-09 | C13: Application Engineering | D13: Custom app dev, microservices, APIs, modernization
B14: TWR-10 | C14: Integration | D14: iPaaS, ESB, event streaming, API management
B15: TWR-11 | C15: ERP | D15: SAP, Oracle, Workday functional & technical delivery
... B25: TWR-21 | C25: Enterprise Architecture | D25: EA, solution & technical architecture, standards

Sheet Capabilities
B2: CAPABILITIES
B3: 139 capabilities. Agent-Amenability (1-5) = how compressible by agents/AI (feeds AI-native model).
B5: ID | C5: Tower | D5: Capability | E5: Scarcity | F5: Agent-Amenability
B6: CAP-001 | C6: Strategy & Transformation | D6: Transformation Strategy | E6: High | F6: 3
B7: CAP-002 | C7: Strategy & Transformation | D7: Operating Model Design | E7: High | F7: 3
B8: CAP-003 | C8: Strategy & Transformation | D8: Value Architecture | E8: Medium | F8: 3
B9: CAP-004 | C9: Strategy & Transformation | D9: Business Case & ROI | E9: Medium | F9: 4
B10: CAP-005 | C10: Industry SMEs | D10: Financial Services Domain | E10: High | F10: 2
B11: CAP-006 | C11: Industry SMEs | D11: Healthcare Domain | E11: High | F11: 2
B12: CAP-007 | C12: Industry SMEs | D12: Retail & CPG Domain | E12: Medium | F12: 2
B13: CAP-008 | C13: Industry SMEs | D13: Manufacturing Domain | E13: Medium | F13: 2
B14: CAP-009 | C14: Industry SMEs | D14: Public Sector Domain | E14: Medium | F14: 2
B15: CAP-010 | C15: Business Process | D15: Process Design | E15: Medium | F15: 4
B16: CAP-011 | C16: Business Process | D16: Process Mining | E16: Medium | F16: 4
B17: CAP-012 | C17: Business Process | D17: Intelligent Automation | E17: High | F17: 5
... B144: CAP-139 | C144: Industry SMEs | D144: Media Domain | E144: Medium | F144: 2

Sheet Career Levels
B2: CAREER LEVEL MODEL
B4: Level | C4: Years Exp | D4: Base Salary (US) | E4: Expectation
B5: Partner | C5: 25+ | D5: =VLOOKUP(B5,Assumptions!$B$50:$D$59,3,FALSE) | E5: Owns client P&L, sells & sponsors transformation
B6: Managing Director | C6: 20+ | D6: =VLOOKUP(B6,Assumptions!$B$50:$D$59,3,FALSE) | E6: Owns portfolio, executive relationships, delivery assurance
B7: Principal | C7: 18+ | D7: =VLOOKUP(B7,Assumptions!$B$50:$D$59,3,FALSE) | E7: Owns large program design and outcomes
B8: Director | C8: 15+ | D8: =VLOOKUP(B8,Assumptions!$B$50:$D$59,3,FALSE) | E8: Owns workstream/program delivery and quality
B9: Senior Manager | C9: 12+ | D9: =VLOOKUP(B9,Assumptions!$B$50:$D$59,3,FALSE) | E9: Leads multiple teams / a delivery track
B10: Manager | C10: 10+ | D10: =VLOOKUP(B10,Assumptions!$B$50:$D$59,3,FALSE) | E10: Leads a team and a deliverable scope
B11: Lead | C11: 8+ | D11: =VLOOKUP(B11,Assumptions!$B$50:$D$59,3,FALSE) | E11: Technical/functional lead for a squad
B12: Senior | C12: 6+ | D12: =VLOOKUP(B12,Assumptions!$B$50:$D$59,3,FALSE) | E12: Independent senior contributor
B13: Intermediate | C13: 3+ | D13: =VLOOKUP(B13,Assumptions!$B$50:$D$59,3,FALSE) | E13: Contributor with guidance
B14: Junior | C14: 0-3 | D14: =VLOOKUP(B14,Assumptions!$B$50:$D$59,3,FALSE) | E14: Entry contributor, supervised

Sheet Roles
B2: ROLE TAXONOMY
B3: 321 roles across 21 towers. Loaded hourly pulls from Internal Cost Model; scarcity adjusts.
B5: ID | C5: Tower | D5: Role | E5: Capability | F5: Scarcity | G5: Min Level | H5: Max Level | I5: Loaded $/hr (min lvl) | J5: Scarcity-Adj $/hr
B6: ROL-001 | C6: Strategy & Transformation | D6: Transformation Partner | E6: Transformation Strategy | F6: High | G6: Partner | H6: Partner | I6: =VLOOKUP(G6,'Internal Cost Model'!$B$6:$F$15,5,FALSE) | J6: =I6*VLOOKUP(F6,Assumptions!$B$43:$C$45,2,FALSE)
B7: ROL-002 | C7: Strategy & Transformation | D7: Transformation Director | E7: Transformation Strategy | F7: High | G7: Director | H7: Principal | I7: =VLOOKUP(G7,'Internal Cost Model'!$B$6:$F$15,5,FALSE) | J7: =I7*VLOOKUP(F7,Assumptions!$B$43:$C$45,2,FALSE)
B8: ROL-003 | C8: Strategy & Transformation | D8: Operating Model Lead | E8: Operating Model Design | F8: High | G8: Senior Manager | H8: Director | I8: =VLOOKUP(G8,'Internal Cost Model'!$B$6:$F$15,5,FALSE) | J8: =I8*VLOOKUP(F8,Assumptions!$B$43:$C$45,2,FALSE)
B9: ROL-004 | C9: Strategy & Transformation | D9: Value Architect | E9: Value Architecture | F9: Medium | G9: Manager | H9: Principal | I9: =VLOOKUP(G9,'Internal Cost Model'!$B$6:$F$15,5,FALSE) | J9: =I9*VLOOKUP(F9,Assumptions!$B$43:$C$45,2,FALSE)
B10: ROL-005 | C10: Strategy & Transformation | D10: Business Case Lead | E10: Business Case & ROI | F10: Medium | G10: Manager | H10: Director | I10: =VLOOKUP(G10,'Internal Cost Model'!$B$6:$F$15,5,FALSE) | J10: =I10*VLOOKUP(F10,Assumptions!$B$43:$C$45,2,FALSE)
B11: ROL-006 | C11: Strategy & Transformation | D11: Transformation Consultant | E11: Transformation Strategy | F11: Medium | G11: Intermediate | H11: Manager | I11: =VLOOKUP(G11,'Internal Cost Model'!$B$6:$F$15,5,FALSE) | J11: =I11*VLOOKUP(F11,Assumptions!$B$43:$C$45,2,FALSE)
B12: ROL-007 | C12: Industry SMEs | D12: Financial Services Principal SME | E12: Financial Services Domain | F12: High | G12: Principal | H12: Managing Director | I12: =VLOOKUP(G12,'Internal Cost Model'!$B$6:$F$15,5,FALSE) | J12: =I12*VLOOKUP(F12,Assumptions!$B$43:$C$45,2,FALSE)
B13: ROL-008 | C13: Industry SMEs | D13: Financial Services Domain Consultant | E13: Financial Services Domain | F13: Medium | G13: Senior | H13: Senior Manager | I13: =VLOOKUP(G13,'Internal Cost Model'!$B$6:$F$15,5,FALSE) | J13: =I13*VLOOKUP(F13,Assumptions!$B$43:$C$45,2,FALSE)
B14: ROL-009 | C14: Industry SMEs | D14: Healthcare Principal SME | E14: Healthcare Domain | F14: High | G14: Principal | H14: Managing Director | I14: =VLOOKUP(G14,'Internal Cost Model'!$B$6:$F$15,5,FALSE) | J14: =I14*VLOOKUP(F14,Assumptions!$B$43:$C$45,2,FALSE)
B15: ROL-010 | C15: Industry SMEs | D15: Healthcare Domain Consultant | E15: Healthcare Domain | F15: Medium | G15: Senior | H15: Senior Manager | I15: =VLOOKUP(G15,'Internal Cost Model'!$B$6:$F$15,5,FALSE) | J15: =I15*VLOOKUP(F15,Assumptions!$B$43:$C$45,2,FALSE)
B16: ROL-011 | C16: Industry SMEs | D16: Retail & CPG Principal SME | E16: Retail & CPG Domain | F16: High | G16: Principal | H16: Managing Director | I16: =VLOOKUP(G16,'Internal Cost Model'!$B$6:$F$15,5,FALSE) | J16: =I16*VLOOKUP(F16,Assumptions!$B$43:$C$45,2,FALSE)
B17: ROL-012 | C17: Industry SMEs | D17: Retail & CPG Domain Consultant | E17: Retail & CPG Domain | F17: Medium | G17: Senior | H17: Senior Manager | I17: =VLOOKUP(G17,'Internal Cost Model'!$B$6:$F$15,5,FALSE) | J17: =I17*VLOOKUP(F17,Assumptions!$B$43:$C$45,2,FALSE)
... B326: ROL-321 | C326: Enterprise Architecture | D326: Data Architect (EA) | E326: Technical Architecture | F326: High | G326: Lead | H326: Senior Manager | I326: =VLOOKUP(G326,'Internal Cost Model'!$B$6:$F$15,5,FALSE) | J326: =I326*VLOOKUP(F326,Assumptions!$B$43:$C$45,2,FALSE)

Sheet Role Rate Card
B2: ROLE RATE CARD — staffable, priced units (role x career level)
B3: Each row is a staffable unit the estimator consumes. Loaded = internal cost; Indicative Bill = SI-T1 onshore market rate. All parametric.
B5: ID | C5: Tower | D5: Role | E5: Capability | F5: Level | G5: Scarcity | H5: Loaded $/hr | I5: Scarcity-Adj $/hr | J5: Indic. Bill $/hr
B6: RC-0001 | C6: Strategy & Transformation | D6: Transformation Partner | E6: Transformation Strategy | F6: Partner | G6: High | H6: =VLOOKUP(F6,'Internal Cost Model'!$B$6:$F$15,5,FALSE) | I6: =H6*VLOOKUP(G6,Assumptions!$B$43:$C$45,2,FALSE) | J6: =VLOOKUP(F6,Assumptions!$B$50:$D$59,2,FALSE)*VLOOKUP("SI-T1",Assumptions!$B$27:$C$31,2,FALSE)*VLOOKUP(G6,Assumptions!$B$43:$C$45,2,FALSE)
B7: RC-0002 | C7: Strategy & Transformation | D7: Transformation Director | E7: Transformation Strategy | F7: Principal | G7: High | H7: =VLOOKUP(F7,'Internal Cost Model'!$B$6:$F$15,5,FALSE) | I7: =H7*VLOOKUP(G7,Assumptions!$B$43:$C$45,2,FALSE) | J7: =VLOOKUP(F7,Assumptions!$B$50:$D$59,2,FALSE)*VLOOKUP("SI-T1",Assumptions!$B$27:$C$31,2,FALSE)*VLOOKUP(G7,Assumptions!$B$43:$C$45,2,FALSE)
B8: RC-0003 | C8: Strategy & Transformation | D8: Transformation Director | E8: Transformation Strategy | F8: Director | G8: High | H8: =VLOOKUP(F8,'Internal Cost Model'!$B$6:$F$15,5,FALSE) | I8: =H8*VLOOKUP(G8,Assumptions!$B$43:$C$45,2,FALSE) | J8: =VLOOKUP(F8,Assumptions!$B$50:$D$59,2,FALSE)*VLOOKUP("SI-T1",Assumptions!$B$27:$C$31,2,FALSE)*VLOOKUP(G8,Assumptions!$B$43:$C$45,2,FALSE)
B9: RC-0004 | C9: Strategy & Transformation | D9: Operating Model Lead | E9: Operating Model Design | F9: Director | G9: High | H9: =VLOOKUP(F9,'Internal Cost Model'!$B$6:$F$15,5,FALSE) | I9: =H9*VLOOKUP(G9,Assumptions!$B$43:$C$45,2,FALSE) | J9: =VLOOKUP(F9,Assumptions!$B$50:$D$59,2,FALSE)*VLOOKUP("SI-T1",Assumptions!$B$27:$C$31,2,FALSE)*VLOOKUP(G9,Assumptions!$B$43:$C$45,2,FALSE)
B10: RC-0005 | C10: Strategy & Transformation | D10: Operating Model Lead | E10: Operating Model Design | F10: Senior Manager | G10: High | H10: =VLOOKUP(F10,'Internal Cost Model'!$B$6:$F$15,5,FALSE) | I10: =H10*VLOOKUP(G10,Assumptions!$B$43:$C$45,2,FALSE) | J10: =VLOOKUP(F10,Assumptions!$B$50:$D$59,2,FALSE)*VLOOKUP("SI-T1",Assumptions!$B$27:$C$31,2,FALSE)*VLOOKUP(G10,Assumptions!$B$43:$C$45,2,FALSE)
B11: RC-0006 | C11: Strategy & Transformation | D11: Value Architect | E11: Value Architecture | F11: Principal | G11: Medium | H11: =VLOOKUP(F11,'Internal Cost Model'!$B$6:$F$15,5,FALSE) | I11: =H11*VLOOKUP(G11,Assumptions!$B$43:$C$45,2,FALSE) | J11: =VLOOKUP(F11,Assumptions!$B$50:$D$59,2,FALSE)*VLOOKUP("SI-T1",Assumptions!$B$27:$C$31,2,FALSE)*VLOOKUP(G11,Assumptions!$B$43:$C$45,2,FALSE)
B12: RC-0007 | C12: Strategy & Transformation | D12: Value Architect | E12: Value Architecture | F12: Director | G12: Medium | H12: =VLOOKUP(F12,'Internal Cost Model'!$B$6:$F$15,5,FALSE) | I12: =H12*VLOOKUP(G12,Assumptions!$B$43:$C$45,2,FALSE) | J12: =VLOOKUP(F12,Assumptions!$B$50:$D$59,2,FALSE)*VLOOKUP("SI-T1",Assumptions!$B$27:$C$31,2,FALSE)*VLOOKUP(G12,Assumptions!$B$43:$C$45,2,FALSE)
B13: RC-0008 | C13: Strategy & Transformation | D13: Value Architect | E13: Value Architecture | F13: Senior Manager | G13: Medium | H13: =VLOOKUP(F13,'Internal Cost Model'!$B$6:$F$15,5,FALSE) | I13: =H13*VLOOKUP(G13,Assumptions!$B$43:$C$45,2,FALSE) | J13: =VLOOKUP(F13,Assumptions!$B$50:$D$59,2,FALSE)*VLOOKUP("SI-T1",Assumptions!$B$27:$C$31,2,FALSE)*VLOOKUP(G13,Assumptions!$B$43:$C$45,2,FALSE)
B14: RC-0009 | C14: Strategy & Transformation | D14: Value Architect | E14: Value Architecture | F14: Manager | G14: Medium | H14: =VLOOKUP(F14,'Internal Cost Model'!$B$6:$F$15,5,FALSE) | I14: =H14*VLOOKUP(G14,Assumptions!$B$43:$C$45,2,FALSE) | J14: =VLOOKUP(F14,Assumptions!$B$50:$D$59,2,FALSE)*VLOOKUP("SI-T1",Assumptions!$B$27:$C$31,2,FALSE)*VLOOKUP(G14,Assumptions!$B$43:$C$45,2,FALSE)
B15: RC-0010 | C15: Strategy & Transformation | D15: Business Case Lead | E15: Business Case & ROI | F15: Director | G15: Medium | H15: =VLOOKUP(F15,'Internal Cost Model'!$B$6:$F$15,5,FALSE) | I15: =H15*VLOOKUP(G15,Assumptions!$B$43:$C$45,2,FALSE) | J15: =VLOOKUP(F15,Assumptions!$B$50:$D$59,2,FALSE)*VLOOKUP("SI-T1",Assumptions!$B$27:$C$31,2,FALSE)*VLOOKUP(G15,Assumptions!$B$43:$C$45,2,FALSE)
B16: RC-0011 | C16: Strategy & Transformation | D16: Business Case Lead | E16: Business Case & ROI | F16: Senior Manager | G16: Medium | H16: =VLOOKUP(F16,'Internal Cost Model'!$B$6:$F$15,5,FALSE) | I16: =H16*VLOOKUP(G16,Assumptions!$B$43:$C$45,2,FALSE) | J16: =VLOOKUP(F16,Assumptions!$B$50:$D$59,2,FALSE)*VLOOKUP("SI-T1",Assumptions!$B$27:$C$31,2,FALSE)*VLOOKUP(G16,Assumptions!$B$43:$C$45,2,FALSE)
B17: RC-0012 | C17: Strategy & Transformation | D17: Business Case Lead | E17: Business Case & ROI | F17: Manager | G17: Medium | H17: =VLOOKUP(F17,'Internal Cost Model'!$B$6:$F$15,5,FALSE) | I17: =H17*VLOOKUP(G17,Assumptions!$B$43:$C$45,2,FALSE) | J17: =VLOOKUP(F17,Assumptions!$B$50:$D$59,2,FALSE)*VLOOKUP("SI-T1",Assumptions!$B$27:$C$31,2,FALSE)*VLOOKUP(G17,Assumptions!$B$43:$C$45,2,FALSE)
... B896: RC-0891 | C896: Enterprise Architecture | D896: Data Architect (EA) | E896: Technical Architecture | F896: Lead | G896: High | H896: =VLOOKUP(F896,'Internal Cost Model'!$B$6:$F$15,5,FALSE) | I896: =H896*VLOOKUP(G896,Assumptions!$B$43:$C$45,2,FALSE) | J896: =VLOOKUP(F896,Assumptions!$B$50:$D$59,2,FALSE)*VLOOKUP("SI-T1",Assumptions!$B$27:$C$31,2,FALSE)*VLOOKUP(G896,Assumptions!$B$43:$C$45,2,FALSE)

Sheet Geography
B2: GEOGRAPHY MODEL
B4: Region | C4: Shore | D4: Salary Mult | E4: Rate Mult | F4: Scarcity Mult | G4: Cost of Living
B5: NYC | C5: Onshore | D5: 1.2 | E5: 1.18 | F5: 1.1 | G5: 1.25
B6: SF / Bay Area | C6: Onshore | D6: 1.25 | E6: 1.22 | F6: 1.15 | G6: 1.3
B7: Seattle | C7: Onshore | D7: 1.15 | E7: 1.12 | F7: 1.1 | G7: 1.18
B8: Chicago | C8: Onshore | D8: 1.05 | E8: 1.05 | F8: 1 | G8: 1.05
B9: Houston | C9: Onshore | D9: 1 | E9: 1 | F9: 1 | G9: 1
B10: Dallas | C10: Onshore | D10: 1 | E10: 1 | F10: 1 | G10: 1
B11: Atlanta | C11: Onshore | D11: 0.98 | E11: 1 | F11: 1 | G11: 0.98
B12: Canada | C12: Nearshore | D12: 0.82 | E12: 0.85 | F12: 0.95 | G12: 0.9
B13: UK | C13: Onshore | D13: 1.05 | E13: 1.08 | F13: 1.05 | G13: 1.1
B14: Western Europe | C14: Onshore | D14: 1.02 | E14: 1.05 | F14: 1.05 | G14: 1.08
B15: Eastern Europe | C15: Nearshore | D15: 0.55 | E15: 0.6 | F15: 0.9 | G15: 0.55
B16: India Tier 1 | C16: Offshore | D16: 0.3 | E16: 0.4 | F16: 0.85 | G16: 0.35
... B21: Australia | C21: Onshore | D21: 1.08 | E21: 1.1 | F21: 1.05 | G21: 1.12

Sheet Internal Cost Model
B2: INTERNAL FULLY-LOADED COST MODEL
B3: Loaded annual = base salary x (1 + total load factor). Loaded hourly = loaded annual / billable hours.
B5: Level | C5: Base Salary | D5: Load Factor | E5: Loaded Annual | F5: Loaded Hourly
B6: Partner | C6: =VLOOKUP(B6,Assumptions!$B$50:$D$59,3,FALSE) | D6: =1+Assumptions!$C$20 | E6: =C6*D6 | F6: =E6/Assumptions!$C$22
B7: Managing Director | C7: =VLOOKUP(B7,Assumptions!$B$50:$D$59,3,FALSE) | D7: =1+Assumptions!$C$20 | E7: =C7*D7 | F7: =E7/Assumptions!$C$22
B8: Principal | C8: =VLOOKUP(B8,Assumptions!$B$50:$D$59,3,FALSE) | D8: =1+Assumptions!$C$20 | E8: =C8*D8 | F8: =E8/Assumptions!$C$22
B9: Director | C9: =VLOOKUP(B9,Assumptions!$B$50:$D$59,3,FALSE) | D9: =1+Assumptions!$C$20 | E9: =C9*D9 | F9: =E9/Assumptions!$C$22
B10: Senior Manager | C10: =VLOOKUP(B10,Assumptions!$B$50:$D$59,3,FALSE) | D10: =1+Assumptions!$C$20 | E10: =C10*D10 | F10: =E10/Assumptions!$C$22
B11: Manager | C11: =VLOOKUP(B11,Assumptions!$B$50:$D$59,3,FALSE) | D11: =1+Assumptions!$C$20 | E11: =C11*D11 | F11: =E11/Assumptions!$C$22
B12: Lead | C12: =VLOOKUP(B12,Assumptions!$B$50:$D$59,3,FALSE) | D12: =1+Assumptions!$C$20 | E12: =C12*D12 | F12: =E12/Assumptions!$C$22
B13: Senior | C13: =VLOOKUP(B13,Assumptions!$B$50:$D$59,3,FALSE) | D13: =1+Assumptions!$C$20 | E13: =C13*D13 | F13: =E13/Assumptions!$C$22
B14: Intermediate | C14: =VLOOKUP(B14,Assumptions!$B$50:$D$59,3,FALSE) | D14: =1+Assumptions!$C$20 | E14: =C14*D14 | F14: =E14/Assumptions!$C$22
B15: Junior | C15: =VLOOKUP(B15,Assumptions!$B$50:$D$59,3,FALSE) | D15: =1+Assumptions!$C$20 | E15: =C15*D15 | F15: =E15/Assumptions!$C$22

Sheet Rate Intelligence
B2: GLOBAL RATE INTELLIGENCE — anonymized provider archetypes
B3: Bill rate = Market Base (onshore, by level) x Provider Tier Mult x Shore Mult. Scarcity applied per role in the estimator. No real firm names.
B5: Provider | C5: Category | D5: Level | E5: Onshore $/hr | F5: Nearshore $/hr | G5: Offshore $/hr | H5: Tier Mult
B6: CONS-T1-A | C6: CONS-T1 | D6: Partner | E6: =VLOOKUP(D6,Assumptions!$B$50:$D$59,2,FALSE)*H6*INDEX(Assumptions!$C$36:$C$38,1) | F6: =VLOOKUP(D6,Assumptions!$B$50:$D$59,2,FALSE)*H6*INDEX(Assumptions!$C$36:$C$38,2) | G6: =VLOOKUP(D6,Assumptions!$B$50:$D$59,2,FALSE)*H6*INDEX(Assumptions!$C$36:$C$38,3) | H6: =VLOOKUP(C6,Assumptions!$B$27:$C$31,2,FALSE)
B7: CONS-T1-A | C7: CONS-T1 | D7: Managing Director | E7: =VLOOKUP(D7,Assumptions!$B$50:$D$59,2,FALSE)*H7*INDEX(Assumptions!$C$36:$C$38,1) | F7: =VLOOKUP(D7,Assumptions!$B$50:$D$59,2,FALSE)*H7*INDEX(Assumptions!$C$36:$C$38,2) | G7: =VLOOKUP(D7,Assumptions!$B$50:$D$59,2,FALSE)*H7*INDEX(Assumptions!$C$36:$C$38,3) | H7: =VLOOKUP(C7,Assumptions!$B$27:$C$31,2,FALSE)
B8: CONS-T1-A | C8: CONS-T1 | D8: Principal | E8: =VLOOKUP(D8,Assumptions!$B$50:$D$59,2,FALSE)*H8*INDEX(Assumptions!$C$36:$C$38,1) | F8: =VLOOKUP(D8,Assumptions!$B$50:$D$59,2,FALSE)*H8*INDEX(Assumptions!$C$36:$C$38,2) | G8: =VLOOKUP(D8,Assumptions!$B$50:$D$59,2,FALSE)*H8*INDEX(Assumptions!$C$36:$C$38,3) | H8: =VLOOKUP(C8,Assumptions!$B$27:$C$31,2,FALSE)
B9: CONS-T1-A | C9: CONS-T1 | D9: Director | E9: =VLOOKUP(D9,Assumptions!$B$50:$D$59,2,FALSE)*H9*INDEX(Assumptions!$C$36:$C$38,1) | F9: =VLOOKUP(D9,Assumptions!$B$50:$D$59,2,FALSE)*H9*INDEX(Assumptions!$C$36:$C$38,2) | G9: =VLOOKUP(D9,Assumptions!$B$50:$D$59,2,FALSE)*H9*INDEX(Assumptions!$C$36:$C$38,3) | H9: =VLOOKUP(C9,Assumptions!$B$27:$C$31,2,FALSE)
B10: CONS-T1-A | C10: CONS-T1 | D10: Senior Manager | E10: =VLOOKUP(D10,Assumptions!$B$50:$D$59,2,FALSE)*H10*INDEX(Assumptions!$C$36:$C$38,1) | F10: =VLOOKUP(D10,Assumptions!$B$50:$D$59,2,FALSE)*H10*INDEX(Assumptions!$C$36:$C$38,2) | G10: =VLOOKUP(D10,Assumptions!$B$50:$D$59,2,FALSE)*H10*INDEX(Assumptions!$C$36:$C$38,3) | H10: =VLOOKUP(C10,Assumptions!$B$27:$C$31,2,FALSE)
B11: CONS-T1-A | C11: CONS-T1 | D11: Manager | E11: =VLOOKUP(D11,Assumptions!$B$50:$D$59,2,FALSE)*H11*INDEX(Assumptions!$C$36:$C$38,1) | F11: =VLOOKUP(D11,Assumptions!$B$50:$D$59,2,FALSE)*H11*INDEX(Assumptions!$C$36:$C$38,2) | G11: =VLOOKUP(D11,Assumptions!$B$50:$D$59,2,FALSE)*H11*INDEX(Assumptions!$C$36:$C$38,3) | H11: =VLOOKUP(C11,Assumptions!$B$27:$C$31,2,FALSE)
B12: CONS-T1-A | C12: CONS-T1 | D12: Lead | E12: =VLOOKUP(D12,Assumptions!$B$50:$D$59,2,FALSE)*H12*INDEX(Assumptions!$C$36:$C$38,1) | F12: =VLOOKUP(D12,Assumptions!$B$50:$D$59,2,FALSE)*H12*INDEX(Assumptions!$C$36:$C$38,2) | G12: =VLOOKUP(D12,Assumptions!$B$50:$D$59,2,FALSE)*H12*INDEX(Assumptions!$C$36:$C$38,3) | H12: =VLOOKUP(C12,Assumptions!$B$27:$C$31,2,FALSE)
B13: CONS-T1-A | C13: CONS-T1 | D13: Senior | E13: =VLOOKUP(D13,Assumptions!$B$50:$D$59,2,FALSE)*H13*INDEX(Assumptions!$C$36:$C$38,1) | F13: =VLOOKUP(D13,Assumptions!$B$50:$D$59,2,FALSE)*H13*INDEX(Assumptions!$C$36:$C$38,2) | G13: =VLOOKUP(D13,Assumptions!$B$50:$D$59,2,FALSE)*H13*INDEX(Assumptions!$C$36:$C$38,3) | H13: =VLOOKUP(C13,Assumptions!$B$27:$C$31,2,FALSE)
B14: CONS-T1-A | C14: CONS-T1 | D14: Intermediate | E14: =VLOOKUP(D14,Assumptions!$B$50:$D$59,2,FALSE)*H14*INDEX(Assumptions!$C$36:$C$38,1) | F14: =VLOOKUP(D14,Assumptions!$B$50:$D$59,2,FALSE)*H14*INDEX(Assumptions!$C$36:$C$38,2) | G14: =VLOOKUP(D14,Assumptions!$B$50:$D$59,2,FALSE)*H14*INDEX(Assumptions!$C$36:$C$38,3) | H14: =VLOOKUP(C14,Assumptions!$B$27:$C$31,2,FALSE)
B15: CONS-T1-A | C15: CONS-T1 | D15: Junior | E15: =VLOOKUP(D15,Assumptions!$B$50:$D$59,2,FALSE)*H15*INDEX(Assumptions!$C$36:$C$38,1) | F15: =VLOOKUP(D15,Assumptions!$B$50:$D$59,2,FALSE)*H15*INDEX(Assumptions!$C$36:$C$38,2) | G15: =VLOOKUP(D15,Assumptions!$B$50:$D$59,2,FALSE)*H15*INDEX(Assumptions!$C$36:$C$38,3) | H15: =VLOOKUP(C15,Assumptions!$B$27:$C$31,2,FALSE)
B16: CONS-T1-B | C16: CONS-T1 | D16: Partner | E16: =VLOOKUP(D16,Assumptions!$B$50:$D$59,2,FALSE)*H16*INDEX(Assumptions!$C$36:$C$38,1) | F16: =VLOOKUP(D16,Assumptions!$B$50:$D$59,2,FALSE)*H16*INDEX(Assumptions!$C$36:$C$38,2) | G16: =VLOOKUP(D16,Assumptions!$B$50:$D$59,2,FALSE)*H16*INDEX(Assumptions!$C$36:$C$38,3) | H16: =VLOOKUP(C16,Assumptions!$B$27:$C$31,2,FALSE)
B17: CONS-T1-B | C17: CONS-T1 | D17: Managing Director | E17: =VLOOKUP(D17,Assumptions!$B$50:$D$59,2,FALSE)*H17*INDEX(Assumptions!$C$36:$C$38,1) | F17: =VLOOKUP(D17,Assumptions!$B$50:$D$59,2,FALSE)*H17*INDEX(Assumptions!$C$36:$C$38,2) | G17: =VLOOKUP(D17,Assumptions!$B$50:$D$59,2,FALSE)*H17*INDEX(Assumptions!$C$36:$C$38,3) | H17: =VLOOKUP(C17,Assumptions!$B$27:$C$31,2,FALSE)
... B235: AI-B4 | C235: AI-B | D235: Junior | E235: =VLOOKUP(D235,Assumptions!$B$50:$D$59,2,FALSE)*H235*INDEX(Assumptions!$C$36:$C$38,1) | F235: =VLOOKUP(D235,Assumptions!$B$50:$D$59,2,FALSE)*H235*INDEX(Assumptions!$C$36:$C$38,2) | G235: =VLOOKUP(D235,Assumptions!$B$50:$D$59,2,FALSE)*H235*INDEX(Assumptions!$C$36:$C$38,3) | H235: =VLOOKUP(C235,Assumptions!$B$27:$C$31,2,FALSE)

Sheet Agent Economics
B2: AI AGENT ECONOMICS (provider-neutral)
B3: Multipliers express capacity gain vs a human-only baseline (1.00 = no gain).
B5: Platform | C5: Type | D5: Monthly $ | E5: Annual $ | F5: Equiv Eng FTE | G5: Util % | H5: Productivity | I5: Documentation | J5: Testing | K5: Architecture
B6: Agent Platform A | C6: General copilot | D6: 2500 | E6: =D6*12 | F6: 0.5 | G6: 0.7 | H6: 1.35 | I6: 1.6 | J6: 1.3 | K6: 1.1
B7: Agent Platform B | C7: Coding agent | D7: 4000 | E7: =D7*12 | F7: 1.2 | G7: 0.75 | H7: 1.8 | I7: 1.5 | J7: 1.9 | K7: 1.25
B8: Agent Platform C | C8: Workflow/RPA agent | D8: 3200 | E8: =D8*12 | F8: 0.8 | G8: 0.65 | H8: 1.5 | I8: 1.4 | J8: 1.45 | K8: 1.1
B9: Agent Platform D | C9: Domain reasoning agent | D9: 6000 | E9: =D9*12 | F9: 1.5 | G9: 0.6 | H9: 1.7 | I9: 1.55 | J9: 1.6 | K9: 1.45
B10: AbarVa Agents | C10: AbarVa-native delivery agents | D10: 3500 | E10: =D10*12 | F10: 1.3 | G10: 0.72 | H10: 1.85 | I10: 1.65 | J10: 1.8 | K10: 1.4

Sheet Delivery Pods
B2: DELIVERY POD LIBRARY
B3: 107 reusable human+agent pods. Est. monthly cost is parametric (headcount x blended loaded monthly).
B5: ID | C5: Pod | D5: Tower | E5: Role Mix | F5: Headcount | G5: Blended Level | H5: Agent Mix | I5: Use Cases / Est. Monthly $
B6: POD-001 | C6: Data Product Pod | D6: Data & Analytics | E6: Data Product Mgr, Data Architect, 3x Data Engineer, BI Dev | F6: 6 | G6: Senior | H6: Agent Platform B + AbarVa Agents | I6: =F6*VLOOKUP(G6,'Internal Cost Model'!$B$6:$F$15,4,FALSE)/12
B7: POD-002 | C7: Snowflake Pod | D7: Data & Analytics | E7: Snowflake Architect, 3x Snowflake Engineer | F7: 4 | G7: Senior | H7: Agent Platform B | I7: =F7*VLOOKUP(G7,'Internal Cost Model'!$B$6:$F$15,4,FALSE)/12
B8: POD-003 | C8: Databricks Pod | D8: Data & Analytics | E8: Databricks Architect, 3x Databricks Engineer | F8: 4 | G8: Senior | H8: Agent Platform B | I8: =F8*VLOOKUP(G8,'Internal Cost Model'!$B$6:$F$15,4,FALSE)/12
B9: POD-004 | C9: Data Governance Pod | D9: Data & Analytics | E9: Governance Lead, 2x Steward, Metadata Lead | F9: 4 | G9: Manager | H9: Agent Platform A | I9: =F9*VLOOKUP(G9,'Internal Cost Model'!$B$6:$F$15,4,FALSE)/12
B10: POD-005 | C10: MDM Pod | D10: Data & Analytics | E10: MDM Architect, 2x Data Engineer | F10: 3 | G10: Lead | H10: Agent Platform B | I10: =F10*VLOOKUP(G10,'Internal Cost Model'!$B$6:$F$15,4,FALSE)/12
B11: POD-006 | C11: AI Platform Pod | D11: AI & GenAI | E11: AI Architect, 2x AI Engineer, MLOps Engineer | F11: 4 | G11: Senior | H11: Agent Platform D + AbarVa Agents | I11: =F11*VLOOKUP(G11,'Internal Cost Model'!$B$6:$F$15,4,FALSE)/12
B12: POD-007 | C12: Agentic AI Pod | D12: AI & GenAI | E12: Agent Architect, FDE, 2x AI Engineer | F12: 4 | G12: Senior | H12: AbarVa Agents + Agent Platform D | I12: =F12*VLOOKUP(G12,'Internal Cost Model'!$B$6:$F$15,4,FALSE)/12
B13: POD-008 | C13: GenAI Pod | D13: AI & GenAI | E13: AI Engineer, Prompt Engineer, LLMOps | F13: 3 | G13: Senior | H13: Agent Platform D | I13: =F13*VLOOKUP(G13,'Internal Cost Model'!$B$6:$F$15,4,FALSE)/12
B14: POD-009 | C14: Responsible AI Pod | D14: AI & GenAI | E14: Responsible AI Lead, Model Validation Lead, AI Governance Lead | F14: 3 | G14: Manager | H14: Agent Platform A | I14: =F14*VLOOKUP(G14,'Internal Cost Model'!$B$6:$F$15,4,FALSE)/12
B15: POD-010 | C15: Adobe Experience Pod | D15: Marketing Technology | E15: AEM Architect, 2x Adobe Developer, Journey Architect | F15: 4 | G15: Senior | H15: Agent Platform A | I15: =F15*VLOOKUP(G15,'Internal Cost Model'!$B$6:$F$15,4,FALSE)/12
B16: POD-011 | C16: CDP Pod | D16: Marketing Technology | E16: CDP Architect, 2x Engineer | F16: 3 | G16: Lead | H16: Agent Platform A | I16: =F16*VLOOKUP(G16,'Internal Cost Model'!$B$6:$F$15,4,FALSE)/12
B17: POD-012 | C17: Workday HCM Pod | D17: ERP | E17: Workday Architect, Functional Lead, 2x Consultant | F17: 4 | G17: Senior | H17: Agent Platform C | I17: =F17*VLOOKUP(G17,'Internal Cost Model'!$B$6:$F$15,4,FALSE)/12
... B112: POD-107 | C112: Payments Fraud AI Pod | D112: Industry SMEs | E112: Payments SME, AI Architect, 2x ML Engineer | F112: 4 | G112: Senior | H112: Agent Platform D | I112: =F112*VLOOKUP(G112,'Internal Cost Model'!$B$6:$F$15,4,FALSE)/12

Sheet Estimation Engine
B2: ESTIMATION ENGINE — traditional vs AI-native (worked example)
B3: One scope, estimated twice. Agents add parallel capacity (faster) and are billed by subscription, not human rate (cheaper). No double-counting.
B5: PROGRAM INPUTS
B6: Program | C6: Customer Data Product Program
B7: Reference delivery pod | C7: Data Product Pod
B8: Onshore mix % | C8: 0.4
B9: Offshore mix % | C9: 0.6
B10: Onshore rate (SI-T1 Senior) $/hr | C10: =VLOOKUP("Senior",Assumptions!$B$50:$D$59,2,FALSE)*VLOOKUP("SI-T1",Assumptions!$B$27:$C$31,2,FALSE)
B11: Offshore rate (SI-T2 Senior) $/hr | C11: =VLOOKUP("Senior",Assumptions!$B$50:$D$59,2,FALSE)*VLOOKUP("SI-T2",Assumptions!$B$27:$C$31,2,FALSE)*INDEX(Assumptions!$C$36:$C$38,3)
B12: Blended rate $/hr | C12: =C8*C10+C9*C11
B13: AI agent platform | C13: AbarVa Agents
B14: Agent equiv FTE / agent | C14: =VLOOKUP(C13,'Agent Economics'!$B$6:$K$10,5,FALSE)
B15: Agent utilization % | C15: =VLOOKUP(C13,'Agent Economics'!$B$6:$K$10,6,FALSE)
B16: Agent annual cost $ | C16: =VLOOKUP(C13,'Agent Economics'!$B$6:$K$10,4,FALSE)
B17: Hours / FTE / month | C17: 173
B19: EFFORT SCOPE (work breakdown)
B20: Estimate Category | C20: Effort Hours | D20: Agent-Amenable
B21: Business Analysis | C21: 1200 | D21: High
B22: Architecture | C22: 1400 | D22: Medium
B23: Engineering | C23: 4500 | D23: High
B24: Testing | C24: 2200 | D24: High
B25: Security | C25: 600 | D25: Medium
B26: Training | C26: 500 | D26: High
B27: Change Management | C27: 500 | D27: Low
B28: Deployment | C28: 700 | D28: Medium
B29: Governance | C29: 400 | D29: Low
B30: Program Management | C30: 1000 | D30: Low
B31: TOTAL EFFORT (hrs) | C31: =SUM(C21:C30)
B33: SCENARIO COMPARISON
B34: Metric | C34: Traditional | D34: AI-Native
B35: Team — humans (FTE) | C35: 18 | D35: 8
B36: AI agents (count) | C36: - | D36: 12
B37: Effective capacity (FTE-equiv) | C37: =C35 | D37: =D35+D36*C14*C15
B38: Timeline (months) | C38: =C31/(C37*C17) | D38: =C31/(D37*C17)
B39: Human effort billed (hrs) | C39: =C31 | D39: =D35*D38*C17
B40: Agent program cost $ | C40: - | D40: =C16*D38/12
B41: TOTAL COST $ | C41: =C39*C12 | D41: =D39*C12+D40

Sheet Business Case
B2: BUSINESS CASE — Traditional vs AI-Native
B3: Pulls live from the Estimation Engine. Edit benefit & discount-rate inputs below.
B5: INPUTS
B6: Annual business benefit $ | C6: 2400000
B7: Discount rate | C7: 0.1
B8: Horizon (years) | C8: 3
B10: Metric | C10: Traditional | D10: AI-Native | E10: Delta
B11: Total cost $ | C11: ='Estimation Engine'!$C$41 | D11: ='Estimation Engine'!$D$41 | E11: ='Estimation Engine'!$C$41-'Estimation Engine'!$D$41
B12: Cost reduction % | E12: =('Estimation Engine'!$C$41-'Estimation Engine'!$D$41)/'Estimation Engine'!$C$41
B13: Timeline (months) | C13: ='Estimation Engine'!$C$38 | D13: ='Estimation Engine'!$D$38 | E13: =('Estimation Engine'!$C$38-'Estimation Engine'!$D$38)/'Estimation Engine'!$C$38
B14: Effort (hours) | C14: ='Estimation Engine'!$C$39 | D14: ='Estimation Engine'!$D$39 | E14: =('Estimation Engine'!$C$39-'Estimation Engine'!$D$39)/'Estimation Engine'!$C$39
B15: Team (FTE) | C15: ='Estimation Engine'!$C$35 | D15: ='Estimation Engine'!$D$35 | E15: ='Estimation Engine'!$C$35-'Estimation Engine'!$D$35
B16: AI agents | D16: ='Estimation Engine'!$D$36
B17: Productivity gain (x) | E17: ='Estimation Engine'!$C$39/'Estimation Engine'!$D$39
B19: VALUE
B20: Benefit over horizon $ | C20: =C6*C8 | D20: =C6*C8
B21: ROI % | C21: =(C6*C8-'Estimation Engine'!$C$41)/'Estimation Engine'!$C$41 | D21: =(C6*C8-'Estimation Engine'!$D$41)/'Estimation Engine'!$D$41
B22: Payback (months) | C22: ='Estimation Engine'!$C$41/(C6/12) | D22: ='Estimation Engine'!$D$41/(C6/12)
B23: NPV $ | C23: =-'Estimation Engine'!$C$41+C6/(1+C7)+C6/(1+C7)^2+C6/(1+C7)^3 | D23: =-'Estimation Engine'!$D$41+C6/(1+C7)+C6/(1+C7)^2+C6/(1+C7)^3
B25: READ | C25: AI-native cuts cost and timeline while improving ROI and payback. All figures trace to the Estimation Engine and the taxonomy substrate — editable and auditable.

Sheet Moves Binding
B2: MOVES ENGINE BINDING MAP
B3: How this taxonomy binds to the AbarVa Move estimation/deliverable engine — one economics source of truth.
B5: Taxonomy Entity | C5: Move Engine Entity | D5: Binding / Use in business case + roadmap
B6: Capability | C6: WorkPackage / Capability scope | D6: Each Move capability scope resolves to one+ taxonomy capabilities; drives WBS
B7: Role + Loaded $/hr | C7: Resource line in effort model | D7: Estimator multiplies WBS effort hours x role scarcity-adjusted rate
B8: Delivery Pod | C8: Staffing model / squad | D8: Pods seed the resource model with a proven human+agent mix
B9: Agent Economics | C9: AI-native scenario | D9: Agent multipliers compress effort hours; cost = agent annual + reduced human FTE
B10: Rate Intelligence | C10: Sourcing / vendor benchmark | D10: Provider archetypes benchmark build vs buy and onshore/near/off mix
B11: Geography | C11: Delivery model | D11: Geo mix sets blended rate and the onshore/nearshore/offshore split
B12: Internal Cost Model | C12: Internal build option | D12: Fully-loaded internal cost = the in-house delivery scenario
B13: Career Levels | C13: Seniority mix | D13: Level mix per WorkPackage drives blended cost and quality posture
B14: Scarcity / Agent-Amenability | C14: Risk + AI-native compression | D14: Scarcity raises cost/risk; agent-amenability sets traditional vs AI-native delta
B16: NOTE | C16: Workbook = editable reference substrate. The estimation/business-case/roadmap COMPUTE runs in-product, consuming these tables. Build that engine phase next.

Sheet Glossary
B2: GLOSSARY
B4: Term | C4: Definition
B5: Fully-loaded cost | C5: Base salary plus all employer load (bonus, equity, benefits, taxes, overhead, bench).
B6: Loaded hourly | C6: Fully-loaded annual cost / billable hours per year.
B7: Provider archetype | C7: Anonymized provider category; no real firm names (liability + neutrality).
B8: Shore | C8: Onshore / nearshore / offshore delivery location class.
B9: Scarcity | C9: Talent-market scarcity tier (High/Med/Low) that adjusts rate and risk.
B10: Agent-amenability | C10: 1-5 score of how compressible a capability is by agents/AI; drives AI-native delta.
B11: Equiv Eng FTE | C11: Human engineering capacity an agent platform approximates.
B12: Productivity multiplier | C12: Capacity gain vs human-only baseline (1.00 = none).
B13: AI-native delivery | C13: People + agents + AI platforms + automation, vs people-only traditional delivery.
B14: Pod | C14: Reusable squad with a defined human+agent role mix and capacity.
