Workbook

Sheet Estimate
A1: ROM estimate — live formulas
A2: Hours = count × unit hours × friction. Weeks = CEILING(hours ÷ (FTE × hours per FTE-week × productive share)). Cost = FTE × weeks × hours per FTE-week × rate. Cached values equal the engine output; money is in cents.
A4: Block | B4: Code | C4: Release | D4: Driver | E4: Count | F4: Unit hours | G4: Friction | H4: Hours | I4: Unit-hours source | J4: Confidence
A5: Use case | B5: UC-1 | C5: R1 | D5: data_source_count | E5: 20 | F5: ='Component Library'!$C$2 -> 36 | G5: ='Assumptions'!$B$2 -> 1.18 | H5: =ROUND(E5*F5*G5,4) -> 849.6 | I5: [A:DL7] synthetic demo benchmark | J5: medium
A6: Use case | B6: UC-1 | C6: R1 | D6: source_table_count | E6: 80 | F6: ='Component Library'!$C$3 -> 8 | G6: ='Assumptions'!$B$2 -> 1.18 | H6: =ROUND(E6*F6*G6,4) -> 755.2 | I6: [A:DL8] synthetic demo benchmark | J6: medium
A7: Use case | B7: UC-1 | C7: R1 | D7: standard_data_entity_count | E7: 55 | F7: ='Component Library'!$C$4 -> 28 | G7: ='Assumptions'!$B$2 -> 1.18 | H7: =ROUND(E7*F7*G7,4) -> 1817.2 | I7: [A:DL9] synthetic demo benchmark | J7: medium
A8: Use case | B8: UC-1 | C8: R1 | D8: dashboard_view_count | E8: 25 | F8: ='Component Library'!$C$5 -> 24 | G8: ='Assumptions'!$B$2 -> 1.18 | H8: =ROUND(E8*F8*G8,4) -> 708 | I8: [A:DL10] synthetic demo benchmark | J8: medium
A9: Use case | B9: UC-1 | C9: R1 | D9: design_row_count | E9: 200 | F9: ='Component Library'!$C$6 -> 3 | G9: ='Assumptions'!$B$2 -> 1.18 | H9: =ROUND(E9*F9*G9,4) -> 708 | I9: [A:DL11] synthetic demo benchmark | J9: medium
A10: Use case | B10: UC-1 | C10: R1 | D10: validation_row_count | E10: 255 | F10: ='Component Library'!$C$7 -> 2 | G10: ='Assumptions'!$B$2 -> 1.18 | H10: =ROUND(E10*F10*G10,4) -> 601.8 | I10: [A:DL12] synthetic demo benchmark | J10: medium
A11: Use case | B11: UC-2 | C11: R2 | D11: data_source_count | E11: 18 | F11: ='Component Library'!$C$2 -> 36 | G11: ='Assumptions'!$B$2 -> 1.18 | H11: =ROUND(E11*F11*G11,4) -> 764.64 | I11: [A:DL7] synthetic demo benchmark | J11: medium
A12: Use case | B12: UC-2 | C12: R2 | D12: source_table_count | E12: 80 | F12: ='Component Library'!$C$3 -> 8 | G12: ='Assumptions'!$B$2 -> 1.18 | H12: =ROUND(E12*F12*G12,4) -> 755.2 | I12: [A:DL8] synthetic demo benchmark | J12: medium
A13: Use case | B13: UC-2 | C13: R2 | D13: standard_data_entity_count | E13: 45 | F13: ='Component Library'!$C$4 -> 28 | G13: ='Assumptions'!$B$2 -> 1.18 | H13: =ROUND(E13*F13*G13,4) -> 1486.8 | I13: [A:DL9] synthetic demo benchmark | J13: medium
A14: Use case | B14: UC-2 | C14: R2 | D14: dashboard_view_count | E14: 30 | F14: ='Component Library'!$C$5 -> 24 | G14: ='Assumptions'!$B$2 -> 1.18 | H14: =ROUND(E14*F14*G14,4) -> 849.6 | I14: [A:DL10] synthetic demo benchmark | J14: medium
A15: Use case | B15: UC-2 | C15: R2 | D15: design_row_count | E15: 150 | F15: ='Component Library'!$C$6 -> 3 | G15: ='Assumptions'!$B$2 -> 1.18 | H15: =ROUND(E15*F15*G15,4) -> 531 | I15: [A:DL11] synthetic demo benchmark | J15: medium
A16: Use case | B16: UC-2 | C16: R2 | D16: validation_row_count | E16: 220 | F16: ='Component Library'!$C$7 -> 2 | G16: ='Assumptions'!$B$2 -> 1.18 | H16: =ROUND(E16*F16*G16,4) -> 519.2 | I16: [A:DL12] synthetic demo benchmark | J16: medium
A17: Foundation | B17: FOUNDATION | C17: shared | D17: data_source_count | E17: 8 | F17: ='Component Library'!$C$2 -> 36 | G17: ='Assumptions'!$B$2 -> 1.18 | H17: =ROUND(E17*F17*G17,4) -> 339.84 | I17: [A:DL7] synthetic demo benchmark | J17: medium
A18: Foundation | B18: FOUNDATION | C18: shared | D18: source_table_count | E18: 65 | F18: ='Component Library'!$C$3 -> 8 | G18: ='Assumptions'!$B$2 -> 1.18 | H18: =ROUND(E18*F18*G18,4) -> 613.6 | I18: [A:DL8] synthetic demo benchmark | J18: medium
A19: Foundation | B19: FOUNDATION | C19: shared | D19: standard_data_entity_count | E19: 20 | F19: ='Component Library'!$C$4 -> 28 | G19: ='Assumptions'!$B$2 -> 1.18 | H19: =ROUND(E19*F19*G19,4) -> 660.8 | I19: [A:DL9] synthetic demo benchmark | J19: medium
A20: Foundation | B20: FOUNDATION | C20: shared | D20: dashboard_view_count | E20: 8 | F20: ='Component Library'!$C$5 -> 24 | G20: ='Assumptions'!$B$2 -> 1.18 | H20: =ROUND(E20*F20*G20,4) -> 226.56 | I20: [A:DL10] synthetic demo benchmark | J20: medium
A21: Foundation | B21: FOUNDATION | C21: shared | D21: design_row_count | E21: 100 | F21: ='Component Library'!$C$6 -> 3 | G21: ='Assumptions'!$B$2 -> 1.18 | H21: =ROUND(E21*F21*G21,4) -> 354 | I21: [A:DL11] synthetic demo benchmark | J21: medium
A22: Foundation | B22: FOUNDATION | C22: shared | D22: validation_row_count | E22: 130 | F22: ='Component Library'!$C$7 -> 2 | G22: ='Assumptions'!$B$2 -> 1.18 | H22: =ROUND(E22*F22*G22,4) -> 306.8 | I22: [A:DL12] synthetic demo benchmark | J22: medium
A24: Block hours | B24: Code | C24: Release | H24: Hours
A25: Use case | B25: UC-1 | C25: R1 | H25: =ROUND(SUM(H5:H10),4) -> 5439.8
A26: Use case | B26: UC-2 | C26: R2 | H26: =ROUND(SUM(H11:H16),4) -> 4906.44
A27: Foundation | B27: FOUNDATION | C27: shared | H27: =ROUND(SUM(H17:H22),4) -> 2501.6
A29: Pod pricing — Release R1 | B29: Certified measures release | C29: not_designed
A30: Adjusted hours | B30: =ROUND(H25,4) -> 5439.8
A31: Paid hours needed (adjusted ÷ productive share) | B31: =B30/'Assumptions'!$B$3 -> 7999.7059
A32: Total FTE | B32: ='Pod & Rates'!$F$6 -> 10
A33: Productive hours per pod-week | B33: =ROUND(B32*'Assumptions'!$B$4*'Assumptions'!$B$3,4) -> 272
A34: Weeks (whole pod-weeks) | B34: =IF(ABS(B30/B33-ROUND(B30/B33,0))<=1E-9,ROUND(B30/B33,0),CEILING(B30/B33,1)) -> 20
A35: Member | B35: Role | C35: Level | D35: FTE | E35: Weeks | F35: Hours per FTE-week | G35: Paid hours | H35: Rate (cents) | I35: Cost (cents) | J35: Role mapping
A36: 1 | B36: ROL-024 | C36: LVL-06 | D36: ='Pod & Rates'!$F$2 -> 1 | E36: =$B$34 -> 20 | F36: ='Assumptions'!$B$4 -> 40 | G36: =ROUND(D36*E36*F36,4) -> 800 | H36: ='Pod & Rates'!$M$2 -> 40625 | I36: =ROUND(G36*H36,0) -> 32500000 | J36: proposed mapping, unapproved
A37: 2 | B37: ROL-023 | C37: LVL-07 | D37: ='Pod & Rates'!$F$3 -> 1 | E37: =$B$34 -> 20 | F37: ='Assumptions'!$B$4 -> 40 | G37: =ROUND(D37*E37*F37,4) -> 800 | H37: ='Pod & Rates'!$M$3 -> 34938 | I37: =ROUND(G37*H37,0) -> 27950400 | J37: proposed mapping, unapproved
A38: 3 | B38: ROL-037 | C38: LVL-08 | D38: ='Pod & Rates'!$F$4 -> 6 | E38: =$B$34 -> 20 | F38: ='Assumptions'!$B$4 -> 40 | G38: =ROUND(D38*E38*F38,4) -> 4800 | H38: ='Pod & Rates'!$M$4 -> 29250 | I38: =ROUND(G38*H38,0) -> 140400000 | J38: proposed mapping, unapproved
A39: 4 | B39: ROL-041 | C39: LVL-08 | D39: ='Pod & Rates'!$F$5 -> 2 | E39: =$B$34 -> 20 | F39: ='Assumptions'!$B$4 -> 40 | G39: =ROUND(D39*E39*F39,4) -> 1600 | H39: ='Pod & Rates'!$M$5 -> 24750 | I39: =ROUND(G39*H39,0) -> 39600000 | J39: proposed mapping, unapproved
A40: Plan cost (cents) | B40: =SUM(I36:I39) -> 240450400
A41: Range low multiplier | B41: ='Assumptions'!$B$12 -> 0.75
A42: Range high multiplier | B42: ='Assumptions'!$B$13 -> 1.5
A43: Low (cents) | B43: =ROUND(B40*B41,0) -> 180337800
...

Sheet Component Library
A1: Driver | B1: Label | C1: Unit hours | D1: Source | E1: Confidence
A2: data_source_count | B2: Data sources | C2: 36 | D2: [A:DL7] synthetic demo benchmark | E2: medium
A3: source_table_count | B3: Source tables | C3: 8 | D3: [A:DL8] synthetic demo benchmark | E3: medium
A4: standard_data_entity_count | B4: Standard data entities | C4: 28 | D4: [A:DL9] synthetic demo benchmark | E4: medium
A5: dashboard_view_count | B5: Dashboard views | C5: 24 | D5: [A:DL10] synthetic demo benchmark | E5: medium
A6: design_row_count | B6: Design rows | C6: 3 | D6: [A:DL11] synthetic demo benchmark | E6: medium
A7: validation_row_count | B7: Validation rows | C7: 2 | D7: [A:DL12] synthetic demo benchmark | E7: medium

Sheet Pod & Rates
A1: # | B1: Role | C1: Level | D1: Location | E1: Provider class | F1: FTE | G1: Base rate (cents) | H1: Base rate source | I1: Location multiplier | J1: Location source | K1: Provider multiplier | L1: Provider source | M1: Hourly rate (cents) | N1: Hourly rate ($) | O1: Rate basis | P1: Role mapping | Q1: Rate provenance | R1: Notes
A2: 1 | B2: ROL-024 | C2: LVL-06 | D2: LOC-DALLAS | E2: SI-T1 | F2: 1 | G2: 40625 | H2: rate_band:ROL-024-LVL-06:indicative_bill_rate [Workforce_Taxonomy_Master.xlsx:Role Rate Card row RC-0069 (Internal Cost Model + Assumptions formula engine, recomputed — see script header)] | I2: 1 | J2: location:LOC-DALLAS:rate_multiplier [Workforce_Taxonomy_Master.xlsx:Geography row 10] | K2: 1 | L2: provider_class:SI-T1/SI-T1 [Workforce_Taxonomy_Master.xlsx:Assumptions row 28] | M2: =ROUND(G2*I2*K2,0) -> 40625 | N2: =M2/100 -> 406.25 | O2: bill_rate | P2: proposed mapping, unapproved | Q2: rate = band ROL-024-LVL-06 indicative_bill_rate $406.25 × location LOC-DALLAS 1.00 × provider 1.00 = $406.25/hr | R2: band rate_basis onshore_si_t1_benchmark (benchmark SI-T1, onshore); band confidence medium, approval global_starter_unapproved; location scarcity_multiplier not applied in this increment; planning rates, not approved
A3: 2 | B3: ROL-023 | C3: LVL-07 | D3: LOC-DALLAS | E3: SI-T1 | F3: 1 | G3: 34938 | H3: rate_band:ROL-023-LVL-07:indicative_bill_rate [Workforce_Taxonomy_Master.xlsx:Role Rate Card row RC-0066 (Internal Cost Model + Assumptions formula engine, recomputed — see script header)] | I3: 1 | J3: location:LOC-DALLAS:rate_multiplier [Workforce_Taxonomy_Master.xlsx:Geography row 10] | K3: 1 | L3: provider_class:SI-T1/SI-T1 [Workforce_Taxonomy_Master.xlsx:Assumptions row 28] | M3: =ROUND(G3*I3*K3,0) -> 34938 | N3: =M3/100 -> 349.38 | O3: bill_rate | P3: proposed mapping, unapproved | Q3: rate = band ROL-023-LVL-07 indicative_bill_rate $349.38 × location LOC-DALLAS 1.00 × provider 1.00 = $349.38/hr | R3: band rate_basis onshore_si_t1_benchmark (benchmark SI-T1, onshore); band confidence medium, approval global_starter_unapproved; location scarcity_multiplier not applied in this increment; planning rates, not approved
A4: 3 | B4: ROL-037 | C4: LVL-08 | D4: LOC-DALLAS | E4: SI-T1 | F4: 6 | G4: 29250 | H4: rate_band:ROL-037-LVL-08:indicative_bill_rate [Workforce_Taxonomy_Master.xlsx:Role Rate Card row RC-0105 (Internal Cost Model + Assumptions formula engine, recomputed — see script header)] | I4: 1 | J4: location:LOC-DALLAS:rate_multiplier [Workforce_Taxonomy_Master.xlsx:Geography row 10] | K4: 1 | L4: provider_class:SI-T1/SI-T1 [Workforce_Taxonomy_Master.xlsx:Assumptions row 28] | M4: =ROUND(G4*I4*K4,0) -> 29250 | N4: =M4/100 -> 292.5 | O4: bill_rate | P4: proposed mapping, unapproved | Q4: rate = band ROL-037-LVL-08 indicative_bill_rate $292.50 × location LOC-DALLAS 1.00 × provider 1.00 = $292.50/hr | R4: band rate_basis onshore_si_t1_benchmark (benchmark SI-T1, onshore); band confidence medium, approval global_starter_unapproved; location scarcity_multiplier not applied in this increment; planning rates, not approved
A5: 4 | B5: ROL-041 | C5: LVL-08 | D5: LOC-DALLAS | E5: SI-T1 | F5: 2 | G5: 24750 | H5: rate_band:ROL-041-LVL-08:indicative_bill_rate [Workforce_Taxonomy_Master.xlsx:Role Rate Card row RC-0116 (Internal Cost Model + Assumptions formula engine, recomputed — see script header)] | I5: 1 | J5: location:LOC-DALLAS:rate_multiplier [Workforce_Taxonomy_Master.xlsx:Geography row 10] | K5: 1 | L5: provider_class:SI-T1/SI-T1 [Workforce_Taxonomy_Master.xlsx:Assumptions row 28] | M5: =ROUND(G5*I5*K5,0) -> 24750 | N5: =M5/100 -> 247.5 | O5: bill_rate | P5: proposed mapping, unapproved | Q5: rate = band ROL-041-LVL-08 indicative_bill_rate $247.50 × location LOC-DALLAS 1.00 × provider 1.00 = $247.50/hr | R5: band rate_basis onshore_si_t1_benchmark (benchmark SI-T1, onshore); band confidence medium, approval global_starter_unapproved; location scarcity_multiplier not applied in this increment; planning rates, not approved
A6: Total FTE | F6: =ROUND(SUM(F2:F5),4) -> 10

Sheet Releases
A1: Release | B1: Name | C1: Design status | D1: Use cases | E1: Hours | F1: Weeks | G1: Low (cents) | H1: Plan (cents) | I1: High (cents) | J1: Shares foundation | K1: Standalone plan (cents) | L1: Low ($) | M1: Plan ($) | N1: High ($)
A2: R1 | B2: Certified measures release | C2: not_designed | D2: UC-1 | E2: ='Estimate'!B30 -> 5439.8 | F2: ='Estimate'!B34 -> 20 | G2: ='Estimate'!B43 -> 180337800 | H2: ='Estimate'!B40 -> 240450400 | I2: ='Estimate'!B44 -> 360675600 | J2: yes | K2: =H2+H4 -> 360675600 | L2: =G2/100 -> 1803378 | M2: =H2/100 -> 2404504 | N2: =I2/100 -> 3606756
A3: R2 | B3: Workbook certification and retirement release | C3: not_designed | D3: UC-2 | E3: ='Estimate'!B47 -> 4906.44 | F3: ='Estimate'!B51 -> 19 | G3: ='Estimate'!B60 -> 171320910 | H3: ='Estimate'!B57 -> 228427880 | I3: ='Estimate'!B61 -> 342641820 | J3: no | K3: =H3 -> 228427880 | L3: =G3/100 -> 1713209.1 | M3: =H3/100 -> 2284278.8 | N3: =I3/100 -> 3426418.2
A4: FOUNDATION | B4: Shared governed data foundation | C4: foundation (not_designed) | D4: shared by R1 | E4: ='Estimate'!B64 -> 2501.6 | F4: ='Estimate'!B68 -> 10 | G4: ='Estimate'!B77 -> 90168900 | H4: ='Estimate'!B74 -> 120225200 | I4: ='Estimate'!B78 -> 180337800 | J4: counted once | L4: =G4/100 -> 901689 | M4: =H4/100 -> 1202252 | N4: =I4/100 -> 1803378
A5: Total | B5: releases + foundation once | E5: =ROUND(SUM(E2:E3)+E4,4) -> 12847.84 | G5: =SUM(G2:G3)+G4 -> 441827610 | H5: =SUM(H2:H3)+H4 -> 589103480 | I5: =SUM(I2:I3)+I4 -> 883655220 | L5: =G5/100 -> 4418276.1 | M5: =H5/100 -> 5891034.8 | N5: =I5/100 -> 8836552.2
A6: Sum of standalone plans | B6: foundation counted in every release that shares it | K6: =SUM(K2:K3) -> 589103480
A7: Double count avoided | B7: standalone sum − total | K7: =K6-H5 -> 0

Sheet Assumptions
A1: Input | B1: Value | C1: Unit | D1: Source | E1: Confidence
A2: Friction factor | B2: 1.18 | C2: multiplier | D2: [A:DL13] synthetic demo benchmark
A3: Productive share | B3: 0.68 | C3: share of paid hours | D3: [A:DL14] synthetic demo benchmark
A4: Hours per FTE-week | B4: 40 | C4: paid hours | D4: [A:DL15] synthetic demo benchmark
A5: Rate basis | B5: bill_rate | D5: ROM structure (caller)
A6: Delivery location | B6: LOC-DALLAS | D6: cost foundation: pricing_delivery_locations
A7: Provider class | B7: SI-T1 | D7: cost foundation: pricing_provider_classes
A8: Pod | B8: ROM-EXPLICIT-POD | D8: ROM structure (caller-specified members)
A9: AI productivity credit | B9: none applied | D9: ROM policy: no credit unless explicitly requested
A10: Rate approval status | B10: planning rates, not approved | D10: Review every role band and delivery mapping before estimate approval
A11: Release R1 design status | B11: not_designed | D11: ROM structure (caller)
A12: Release R1 range low | B12: 0.75 | C12: multiplier | D12: ROM policy ROM-NOT-DESIGNED: not-designed band
A13: Release R1 range high | B13: 1.5 | C13: multiplier | D13: ROM policy ROM-NOT-DESIGNED: not-designed band
A14: Release R2 design status | B14: not_designed | D14: ROM structure (caller)
A15: Release R2 range low | B15: 0.75 | C15: multiplier | D15: ROM policy ROM-NOT-DESIGNED: not-designed band
A16: Release R2 range high | B16: 1.5 | C16: multiplier | D16: ROM policy ROM-NOT-DESIGNED: not-designed band
A17: Foundation FOUNDATION design status | B17: not_designed | D17: ROM structure (caller)
A18: Foundation FOUNDATION range low | B18: 0.75 | C18: multiplier | D18: ROM policy ROM-NOT-DESIGNED: not-designed band
A19: Foundation FOUNDATION range high | B19: 1.5 | C19: multiplier | D19: ROM policy ROM-NOT-DESIGNED: not-designed band
A20: Unit hours: data_source_count | B20: ='Component Library'!$C$2 -> 36 | C20: hours per unit | D20: [A:DL7] synthetic demo benchmark | E20: medium
A21: Unit hours: source_table_count | B21: ='Component Library'!$C$3 -> 8 | C21: hours per unit | D21: [A:DL8] synthetic demo benchmark | E21: medium
A22: Unit hours: standard_data_entity_count | B22: ='Component Library'!$C$4 -> 28 | C22: hours per unit | D22: [A:DL9] synthetic demo benchmark | E22: medium
A23: Unit hours: dashboard_view_count | B23: ='Component Library'!$C$5 -> 24 | C23: hours per unit | D23: [A:DL10] synthetic demo benchmark | E23: medium
A24: Unit hours: design_row_count | B24: ='Component Library'!$C$6 -> 3 | C24: hours per unit | D24: [A:DL11] synthetic demo benchmark | E24: medium
A25: Unit hours: validation_row_count | B25: ='Component Library'!$C$7 -> 2 | C25: hours per unit | D25: [A:DL12] synthetic demo benchmark | E25: medium
A26: Count: UC-1 data_source_count | B26: ='Estimate'!$E$5 -> 20 | C26: units | D26: ROM structure (caller)
A27: Count: UC-1 source_table_count | B27: ='Estimate'!$E$6 -> 80 | C27: units | D27: ROM structure (caller)
A28: Count: UC-1 standard_data_entity_count | B28: ='Estimate'!$E$7 -> 55 | C28: units | D28: ROM structure (caller)
A29: Count: UC-1 dashboard_view_count | B29: ='Estimate'!$E$8 -> 25 | C29: units | D29: ROM structure (caller)
A30: Count: UC-1 design_row_count | B30: ='Estimate'!$E$9 -> 200 | C30: units | D30: ROM structure (caller)
A31: Count: UC-1 validation_row_count | B31: ='Estimate'!$E$10 -> 255 | C31: units | D31: ROM structure (caller)
A32: Count: UC-2 data_source_count | B32: ='Estimate'!$E$11 -> 18 | C32: units | D32: ROM structure (caller)
A33: Count: UC-2 source_table_count | B33: ='Estimate'!$E$12 -> 80 | C33: units | D33: ROM structure (caller)
A34: Count: UC-2 standard_data_entity_count | B34: ='Estimate'!$E$13 -> 45 | C34: units | D34: ROM structure (caller)
A35: Count: UC-2 dashboard_view_count | B35: ='Estimate'!$E$14 -> 30 | C35: units | D35: ROM structure (caller)
A36: Count: UC-2 design_row_count | B36: ='Estimate'!$E$15 -> 150 | C36: units | D36: ROM structure (caller)
A37: Count: UC-2 validation_row_count | B37: ='Estimate'!$E$16 -> 220 | C37: units | D37: ROM structure (caller)
A38: Count: FOUNDATION data_source_count | B38: ='Estimate'!$E$17 -> 8 | C38: units | D38: ROM structure (caller)
A39: Count: FOUNDATION source_table_count | B39: ='Estimate'!$E$18 -> 65 | C39: units | D39: ROM structure (caller)
A40: Count: FOUNDATION standard_data_entity_count | B40: ='Estimate'!$E$19 -> 20 | C40: units | D40: ROM structure (caller)
...
